[2024-09-02T21:34:52.607+0000] {processor.py:161} INFO - Started process (PID=70) to work on /opt/airflow/dags/etl_dag.py
[2024-09-02T21:34:52.627+0000] {processor.py:830} INFO - Processing file /opt/airflow/dags/etl_dag.py for tasks to queue
[2024-09-02T21:34:52.638+0000] {logging_mixin.py:188} INFO - [2024-09-02T21:34:52.637+0000] {dagbag.py:545} INFO - Filling up the DagBag from /opt/airflow/dags/etl_dag.py
[2024-09-02T21:34:52.814+0000] {logging_mixin.py:188} INFO - [2024-09-02T21:34:52.789+0000] {dagbag.py:355} ERROR - Failed to import: /opt/airflow/dags/etl_dag.py
Traceback (most recent call last):
  File "/home/airflow/.local/lib/python3.12/site-packages/airflow/models/dagbag.py", line 351, in parse
    loader.exec_module(new_module)
  File "<frozen importlib._bootstrap_external>", line 995, in exec_module
  File "<frozen importlib._bootstrap>", line 488, in _call_with_frames_removed
  File "/opt/airflow/dags/etl_dag.py", line 3, in <module>
    from airflow.operators.ptyhon import PythonOperator
ModuleNotFoundError: No module named 'airflow.operators.ptyhon'
[2024-09-02T21:34:52.830+0000] {processor.py:842} WARNING - No viable dags retrieved from /opt/airflow/dags/etl_dag.py
[2024-09-02T21:34:53.484+0000] {processor.py:183} INFO - Processing /opt/airflow/dags/etl_dag.py took 1.006 seconds
[2024-09-02T21:35:27.359+0000] {processor.py:161} INFO - Started process (PID=136) to work on /opt/airflow/dags/etl_dag.py
[2024-09-02T21:35:27.363+0000] {processor.py:830} INFO - Processing file /opt/airflow/dags/etl_dag.py for tasks to queue
[2024-09-02T21:35:27.371+0000] {logging_mixin.py:188} INFO - [2024-09-02T21:35:27.370+0000] {dagbag.py:545} INFO - Filling up the DagBag from /opt/airflow/dags/etl_dag.py
[2024-09-02T21:35:27.441+0000] {logging_mixin.py:188} INFO - [2024-09-02T21:35:27.426+0000] {dagbag.py:355} ERROR - Failed to import: /opt/airflow/dags/etl_dag.py
Traceback (most recent call last):
  File "/home/airflow/.local/lib/python3.12/site-packages/airflow/models/dagbag.py", line 351, in parse
    loader.exec_module(new_module)
  File "<frozen importlib._bootstrap_external>", line 995, in exec_module
  File "<frozen importlib._bootstrap>", line 488, in _call_with_frames_removed
  File "/opt/airflow/dags/etl_dag.py", line 3, in <module>
    from airflow.operators.ptyhon import PythonOperator
ModuleNotFoundError: No module named 'airflow.operators.ptyhon'
[2024-09-02T21:35:27.445+0000] {processor.py:842} WARNING - No viable dags retrieved from /opt/airflow/dags/etl_dag.py
[2024-09-02T21:35:27.537+0000] {processor.py:183} INFO - Processing /opt/airflow/dags/etl_dag.py took 0.204 seconds
[2024-09-02T21:36:01.147+0000] {processor.py:161} INFO - Started process (PID=193) to work on /opt/airflow/dags/etl_dag.py
[2024-09-02T21:36:01.152+0000] {processor.py:830} INFO - Processing file /opt/airflow/dags/etl_dag.py for tasks to queue
[2024-09-02T21:36:01.187+0000] {logging_mixin.py:188} INFO - [2024-09-02T21:36:01.186+0000] {dagbag.py:545} INFO - Filling up the DagBag from /opt/airflow/dags/etl_dag.py
[2024-09-02T21:36:04.450+0000] {logging_mixin.py:188} INFO - [2024-09-02T21:36:04.375+0000] {dagbag.py:355} ERROR - Failed to import: /opt/airflow/dags/etl_dag.py
Traceback (most recent call last):
  File "/home/airflow/.local/lib/python3.12/site-packages/airflow/models/dagbag.py", line 351, in parse
    loader.exec_module(new_module)
  File "<frozen importlib._bootstrap_external>", line 995, in exec_module
  File "<frozen importlib._bootstrap>", line 488, in _call_with_frames_removed
  File "/opt/airflow/dags/etl_dag.py", line 21, in <module>
    with DAG(
         ^^^^
  File "/home/airflow/.local/lib/python3.12/site-packages/airflow/models/dag.py", line 543, in __init__
    if start_date and start_date.tzinfo:
                      ^^^^^^^^^^^^^^^^^
AttributeError: 'datetime.date' object has no attribute 'tzinfo'
[2024-09-02T21:36:04.458+0000] {processor.py:842} WARNING - No viable dags retrieved from /opt/airflow/dags/etl_dag.py
[2024-09-02T21:36:04.540+0000] {processor.py:183} INFO - Processing /opt/airflow/dags/etl_dag.py took 3.456 seconds
[2024-09-02T21:38:31.238+0000] {processor.py:161} INFO - Started process (PID=67) to work on /opt/airflow/dags/etl_dag.py
[2024-09-02T21:38:31.243+0000] {processor.py:830} INFO - Processing file /opt/airflow/dags/etl_dag.py for tasks to queue
[2024-09-02T21:38:31.251+0000] {logging_mixin.py:188} INFO - [2024-09-02T21:38:31.250+0000] {dagbag.py:545} INFO - Filling up the DagBag from /opt/airflow/dags/etl_dag.py
[2024-09-02T21:38:34.819+0000] {logging_mixin.py:188} INFO - [2024-09-02T21:38:34.795+0000] {dagbag.py:355} ERROR - Failed to import: /opt/airflow/dags/etl_dag.py
Traceback (most recent call last):
  File "/home/airflow/.local/lib/python3.12/site-packages/airflow/models/dagbag.py", line 351, in parse
    loader.exec_module(new_module)
  File "<frozen importlib._bootstrap_external>", line 995, in exec_module
  File "<frozen importlib._bootstrap>", line 488, in _call_with_frames_removed
  File "/opt/airflow/dags/etl_dag.py", line 21, in <module>
    with DAG(
         ^^^^
  File "/home/airflow/.local/lib/python3.12/site-packages/airflow/models/dag.py", line 543, in __init__
    if start_date and start_date.tzinfo:
                      ^^^^^^^^^^^^^^^^^
AttributeError: 'datetime.date' object has no attribute 'tzinfo'
[2024-09-02T21:38:34.825+0000] {processor.py:842} WARNING - No viable dags retrieved from /opt/airflow/dags/etl_dag.py
[2024-09-02T21:38:34.888+0000] {processor.py:183} INFO - Processing /opt/airflow/dags/etl_dag.py took 3.672 seconds
[2024-09-02T21:39:05.815+0000] {processor.py:161} INFO - Started process (PID=132) to work on /opt/airflow/dags/etl_dag.py
[2024-09-02T21:39:05.819+0000] {processor.py:830} INFO - Processing file /opt/airflow/dags/etl_dag.py for tasks to queue
[2024-09-02T21:39:05.823+0000] {logging_mixin.py:188} INFO - [2024-09-02T21:39:05.822+0000] {dagbag.py:545} INFO - Filling up the DagBag from /opt/airflow/dags/etl_dag.py
[2024-09-02T21:39:06.785+0000] {logging_mixin.py:188} INFO - [2024-09-02T21:39:06.772+0000] {dagbag.py:355} ERROR - Failed to import: /opt/airflow/dags/etl_dag.py
Traceback (most recent call last):
  File "/home/airflow/.local/lib/python3.12/site-packages/airflow/models/dagbag.py", line 351, in parse
    loader.exec_module(new_module)
  File "<frozen importlib._bootstrap_external>", line 995, in exec_module
  File "<frozen importlib._bootstrap>", line 488, in _call_with_frames_removed
  File "/opt/airflow/dags/etl_dag.py", line 21, in <module>
    with DAG(
         ^^^^
  File "/home/airflow/.local/lib/python3.12/site-packages/airflow/models/dag.py", line 543, in __init__
    if start_date and start_date.tzinfo:
                      ^^^^^^^^^^^^^^^^^
AttributeError: 'datetime.date' object has no attribute 'tzinfo'
[2024-09-02T21:39:06.788+0000] {processor.py:842} WARNING - No viable dags retrieved from /opt/airflow/dags/etl_dag.py
[2024-09-02T21:39:06.816+0000] {processor.py:183} INFO - Processing /opt/airflow/dags/etl_dag.py took 1.013 seconds
[2024-09-02T21:39:37.690+0000] {processor.py:161} INFO - Started process (PID=195) to work on /opt/airflow/dags/etl_dag.py
[2024-09-02T21:39:37.691+0000] {processor.py:830} INFO - Processing file /opt/airflow/dags/etl_dag.py for tasks to queue
[2024-09-02T21:39:37.693+0000] {logging_mixin.py:188} INFO - [2024-09-02T21:39:37.693+0000] {dagbag.py:545} INFO - Filling up the DagBag from /opt/airflow/dags/etl_dag.py
[2024-09-02T21:39:38.279+0000] {logging_mixin.py:188} INFO - [2024-09-02T21:39:38.272+0000] {dagbag.py:355} ERROR - Failed to import: /opt/airflow/dags/etl_dag.py
Traceback (most recent call last):
  File "/home/airflow/.local/lib/python3.12/site-packages/airflow/models/dagbag.py", line 351, in parse
    loader.exec_module(new_module)
  File "<frozen importlib._bootstrap_external>", line 995, in exec_module
  File "<frozen importlib._bootstrap>", line 488, in _call_with_frames_removed
  File "/opt/airflow/dags/etl_dag.py", line 21, in <module>
    with DAG(
         ^^^^
  File "/home/airflow/.local/lib/python3.12/site-packages/airflow/models/dag.py", line 543, in __init__
    if start_date and start_date.tzinfo:
                      ^^^^^^^^^^^^^^^^^
AttributeError: 'datetime.date' object has no attribute 'tzinfo'
[2024-09-02T21:39:38.282+0000] {processor.py:842} WARNING - No viable dags retrieved from /opt/airflow/dags/etl_dag.py
[2024-09-02T21:39:38.306+0000] {processor.py:183} INFO - Processing /opt/airflow/dags/etl_dag.py took 0.622 seconds
[2024-09-02T21:40:08.396+0000] {processor.py:161} INFO - Started process (PID=257) to work on /opt/airflow/dags/etl_dag.py
[2024-09-02T21:40:08.397+0000] {processor.py:830} INFO - Processing file /opt/airflow/dags/etl_dag.py for tasks to queue
[2024-09-02T21:40:08.400+0000] {logging_mixin.py:188} INFO - [2024-09-02T21:40:08.399+0000] {dagbag.py:545} INFO - Filling up the DagBag from /opt/airflow/dags/etl_dag.py
[2024-09-02T21:40:08.911+0000] {logging_mixin.py:188} INFO - [2024-09-02T21:40:08.905+0000] {dagbag.py:355} ERROR - Failed to import: /opt/airflow/dags/etl_dag.py
Traceback (most recent call last):
  File "/home/airflow/.local/lib/python3.12/site-packages/airflow/models/dagbag.py", line 351, in parse
    loader.exec_module(new_module)
  File "<frozen importlib._bootstrap_external>", line 995, in exec_module
  File "<frozen importlib._bootstrap>", line 488, in _call_with_frames_removed
  File "/opt/airflow/dags/etl_dag.py", line 21, in <module>
    with DAG(
         ^^^^
  File "/home/airflow/.local/lib/python3.12/site-packages/airflow/models/dag.py", line 543, in __init__
    if start_date and start_date.tzinfo:
                      ^^^^^^^^^^^^^^^^^
AttributeError: 'datetime.date' object has no attribute 'tzinfo'
[2024-09-02T21:40:08.914+0000] {processor.py:842} WARNING - No viable dags retrieved from /opt/airflow/dags/etl_dag.py
[2024-09-02T21:40:08.927+0000] {processor.py:183} INFO - Processing /opt/airflow/dags/etl_dag.py took 0.541 seconds
[2024-09-02T21:40:39.566+0000] {processor.py:161} INFO - Started process (PID=317) to work on /opt/airflow/dags/etl_dag.py
[2024-09-02T21:40:39.568+0000] {processor.py:830} INFO - Processing file /opt/airflow/dags/etl_dag.py for tasks to queue
[2024-09-02T21:40:39.572+0000] {logging_mixin.py:188} INFO - [2024-09-02T21:40:39.571+0000] {dagbag.py:545} INFO - Filling up the DagBag from /opt/airflow/dags/etl_dag.py
[2024-09-02T21:40:40.288+0000] {logging_mixin.py:188} INFO - [2024-09-02T21:40:40.279+0000] {dagbag.py:355} ERROR - Failed to import: /opt/airflow/dags/etl_dag.py
Traceback (most recent call last):
  File "/home/airflow/.local/lib/python3.12/site-packages/airflow/models/dagbag.py", line 351, in parse
    loader.exec_module(new_module)
  File "<frozen importlib._bootstrap_external>", line 995, in exec_module
  File "<frozen importlib._bootstrap>", line 488, in _call_with_frames_removed
  File "/opt/airflow/dags/etl_dag.py", line 21, in <module>
    with DAG(
         ^^^^
  File "/home/airflow/.local/lib/python3.12/site-packages/airflow/models/dag.py", line 543, in __init__
    if start_date and start_date.tzinfo:
                      ^^^^^^^^^^^^^^^^^
AttributeError: 'datetime.date' object has no attribute 'tzinfo'
[2024-09-02T21:40:40.292+0000] {processor.py:842} WARNING - No viable dags retrieved from /opt/airflow/dags/etl_dag.py
[2024-09-02T21:40:40.319+0000] {processor.py:183} INFO - Processing /opt/airflow/dags/etl_dag.py took 0.762 seconds
[2024-09-02T21:41:11.190+0000] {processor.py:161} INFO - Started process (PID=384) to work on /opt/airflow/dags/etl_dag.py
[2024-09-02T21:41:11.191+0000] {processor.py:830} INFO - Processing file /opt/airflow/dags/etl_dag.py for tasks to queue
[2024-09-02T21:41:11.194+0000] {logging_mixin.py:188} INFO - [2024-09-02T21:41:11.194+0000] {dagbag.py:545} INFO - Filling up the DagBag from /opt/airflow/dags/etl_dag.py
[2024-09-02T21:41:11.961+0000] {logging_mixin.py:188} INFO - [2024-09-02T21:41:11.950+0000] {dagbag.py:355} ERROR - Failed to import: /opt/airflow/dags/etl_dag.py
Traceback (most recent call last):
  File "/home/airflow/.local/lib/python3.12/site-packages/airflow/models/dagbag.py", line 351, in parse
    loader.exec_module(new_module)
  File "<frozen importlib._bootstrap_external>", line 995, in exec_module
  File "<frozen importlib._bootstrap>", line 488, in _call_with_frames_removed
  File "/opt/airflow/dags/etl_dag.py", line 21, in <module>
    with DAG(
         ^^^^
  File "/home/airflow/.local/lib/python3.12/site-packages/airflow/models/dag.py", line 543, in __init__
    if start_date and start_date.tzinfo:
                      ^^^^^^^^^^^^^^^^^
AttributeError: 'datetime.date' object has no attribute 'tzinfo'
[2024-09-02T21:41:11.964+0000] {processor.py:842} WARNING - No viable dags retrieved from /opt/airflow/dags/etl_dag.py
[2024-09-02T21:41:11.989+0000] {processor.py:183} INFO - Processing /opt/airflow/dags/etl_dag.py took 0.809 seconds
[2024-09-02T21:44:25.432+0000] {processor.py:161} INFO - Started process (PID=68) to work on /opt/airflow/dags/etl_dag.py
[2024-09-02T21:44:25.435+0000] {processor.py:830} INFO - Processing file /opt/airflow/dags/etl_dag.py for tasks to queue
[2024-09-02T21:44:25.440+0000] {logging_mixin.py:188} INFO - [2024-09-02T21:44:25.439+0000] {dagbag.py:545} INFO - Filling up the DagBag from /opt/airflow/dags/etl_dag.py
[2024-09-02T21:44:29.131+0000] {logging_mixin.py:188} INFO - [2024-09-02T21:44:29.109+0000] {dagbag.py:355} ERROR - Failed to import: /opt/airflow/dags/etl_dag.py
Traceback (most recent call last):
  File "/home/airflow/.local/lib/python3.12/site-packages/airflow/models/dagbag.py", line 351, in parse
    loader.exec_module(new_module)
  File "<frozen importlib._bootstrap_external>", line 995, in exec_module
  File "<frozen importlib._bootstrap>", line 488, in _call_with_frames_removed
  File "/opt/airflow/dags/etl_dag.py", line 21, in <module>
    with DAG(
         ^^^^
  File "/home/airflow/.local/lib/python3.12/site-packages/airflow/models/dag.py", line 543, in __init__
    if start_date and start_date.tzinfo:
                      ^^^^^^^^^^^^^^^^^
AttributeError: 'datetime.date' object has no attribute 'tzinfo'
[2024-09-02T21:44:29.140+0000] {processor.py:842} WARNING - No viable dags retrieved from /opt/airflow/dags/etl_dag.py
[2024-09-02T21:44:29.219+0000] {processor.py:183} INFO - Processing /opt/airflow/dags/etl_dag.py took 3.807 seconds
[2024-09-02T21:44:59.467+0000] {processor.py:161} INFO - Started process (PID=132) to work on /opt/airflow/dags/etl_dag.py
[2024-09-02T21:44:59.469+0000] {processor.py:830} INFO - Processing file /opt/airflow/dags/etl_dag.py for tasks to queue
[2024-09-02T21:44:59.473+0000] {logging_mixin.py:188} INFO - [2024-09-02T21:44:59.472+0000] {dagbag.py:545} INFO - Filling up the DagBag from /opt/airflow/dags/etl_dag.py
[2024-09-02T21:45:00.189+0000] {logging_mixin.py:188} INFO - [2024-09-02T21:45:00.181+0000] {dagbag.py:355} ERROR - Failed to import: /opt/airflow/dags/etl_dag.py
Traceback (most recent call last):
  File "/home/airflow/.local/lib/python3.12/site-packages/airflow/models/dagbag.py", line 351, in parse
    loader.exec_module(new_module)
  File "<frozen importlib._bootstrap_external>", line 995, in exec_module
  File "<frozen importlib._bootstrap>", line 488, in _call_with_frames_removed
  File "/opt/airflow/dags/etl_dag.py", line 21, in <module>
    with DAG(
         ^^^^
  File "/home/airflow/.local/lib/python3.12/site-packages/airflow/models/dag.py", line 543, in __init__
    if start_date and start_date.tzinfo:
                      ^^^^^^^^^^^^^^^^^
AttributeError: 'datetime.date' object has no attribute 'tzinfo'
[2024-09-02T21:45:00.191+0000] {processor.py:842} WARNING - No viable dags retrieved from /opt/airflow/dags/etl_dag.py
[2024-09-02T21:45:00.206+0000] {processor.py:183} INFO - Processing /opt/airflow/dags/etl_dag.py took 0.751 seconds
[2024-09-02T21:45:31.080+0000] {processor.py:161} INFO - Started process (PID=193) to work on /opt/airflow/dags/etl_dag.py
[2024-09-02T21:45:31.081+0000] {processor.py:830} INFO - Processing file /opt/airflow/dags/etl_dag.py for tasks to queue
[2024-09-02T21:45:31.083+0000] {logging_mixin.py:188} INFO - [2024-09-02T21:45:31.083+0000] {dagbag.py:545} INFO - Filling up the DagBag from /opt/airflow/dags/etl_dag.py
[2024-09-02T21:45:31.592+0000] {logging_mixin.py:188} INFO - [2024-09-02T21:45:31.582+0000] {dagbag.py:355} ERROR - Failed to import: /opt/airflow/dags/etl_dag.py
Traceback (most recent call last):
  File "/home/airflow/.local/lib/python3.12/site-packages/airflow/models/dagbag.py", line 351, in parse
    loader.exec_module(new_module)
  File "<frozen importlib._bootstrap_external>", line 995, in exec_module
  File "<frozen importlib._bootstrap>", line 488, in _call_with_frames_removed
  File "/opt/airflow/dags/etl_dag.py", line 21, in <module>
    with DAG(
         ^^^^
  File "/home/airflow/.local/lib/python3.12/site-packages/airflow/models/dag.py", line 543, in __init__
    if start_date and start_date.tzinfo:
                      ^^^^^^^^^^^^^^^^^
AttributeError: 'datetime.date' object has no attribute 'tzinfo'
[2024-09-02T21:45:31.595+0000] {processor.py:842} WARNING - No viable dags retrieved from /opt/airflow/dags/etl_dag.py
[2024-09-02T21:45:31.610+0000] {processor.py:183} INFO - Processing /opt/airflow/dags/etl_dag.py took 0.536 seconds
[2024-09-02T21:46:02.454+0000] {processor.py:161} INFO - Started process (PID=256) to work on /opt/airflow/dags/etl_dag.py
[2024-09-02T21:46:02.456+0000] {processor.py:830} INFO - Processing file /opt/airflow/dags/etl_dag.py for tasks to queue
[2024-09-02T21:46:02.459+0000] {logging_mixin.py:188} INFO - [2024-09-02T21:46:02.458+0000] {dagbag.py:545} INFO - Filling up the DagBag from /opt/airflow/dags/etl_dag.py
[2024-09-02T21:46:03.147+0000] {logging_mixin.py:188} INFO - [2024-09-02T21:46:03.137+0000] {dagbag.py:355} ERROR - Failed to import: /opt/airflow/dags/etl_dag.py
Traceback (most recent call last):
  File "/home/airflow/.local/lib/python3.12/site-packages/airflow/models/dagbag.py", line 351, in parse
    loader.exec_module(new_module)
  File "<frozen importlib._bootstrap_external>", line 995, in exec_module
  File "<frozen importlib._bootstrap>", line 488, in _call_with_frames_removed
  File "/opt/airflow/dags/etl_dag.py", line 21, in <module>
    with DAG(
         ^^^^
  File "/home/airflow/.local/lib/python3.12/site-packages/airflow/models/dag.py", line 543, in __init__
    if start_date and start_date.tzinfo:
                      ^^^^^^^^^^^^^^^^^
AttributeError: 'datetime.date' object has no attribute 'tzinfo'
[2024-09-02T21:46:03.151+0000] {processor.py:842} WARNING - No viable dags retrieved from /opt/airflow/dags/etl_dag.py
[2024-09-02T21:46:03.169+0000] {processor.py:183} INFO - Processing /opt/airflow/dags/etl_dag.py took 0.726 seconds
[2024-09-02T21:46:33.280+0000] {processor.py:161} INFO - Started process (PID=320) to work on /opt/airflow/dags/etl_dag.py
[2024-09-02T21:46:33.281+0000] {processor.py:830} INFO - Processing file /opt/airflow/dags/etl_dag.py for tasks to queue
[2024-09-02T21:46:33.283+0000] {logging_mixin.py:188} INFO - [2024-09-02T21:46:33.283+0000] {dagbag.py:545} INFO - Filling up the DagBag from /opt/airflow/dags/etl_dag.py
[2024-09-02T21:46:33.828+0000] {logging_mixin.py:188} INFO - [2024-09-02T21:46:33.823+0000] {dagbag.py:355} ERROR - Failed to import: /opt/airflow/dags/etl_dag.py
Traceback (most recent call last):
  File "/home/airflow/.local/lib/python3.12/site-packages/airflow/models/dagbag.py", line 351, in parse
    loader.exec_module(new_module)
  File "<frozen importlib._bootstrap_external>", line 995, in exec_module
  File "<frozen importlib._bootstrap>", line 488, in _call_with_frames_removed
  File "/opt/airflow/dags/etl_dag.py", line 21, in <module>
    with DAG(
         ^^^^
  File "/home/airflow/.local/lib/python3.12/site-packages/airflow/models/dag.py", line 543, in __init__
    if start_date and start_date.tzinfo:
                      ^^^^^^^^^^^^^^^^^
AttributeError: 'datetime.date' object has no attribute 'tzinfo'
[2024-09-02T21:46:33.832+0000] {processor.py:842} WARNING - No viable dags retrieved from /opt/airflow/dags/etl_dag.py
[2024-09-02T21:46:33.871+0000] {processor.py:183} INFO - Processing /opt/airflow/dags/etl_dag.py took 0.596 seconds
[2024-09-02T21:46:59.545+0000] {processor.py:161} INFO - Started process (PID=369) to work on /opt/airflow/dags/etl_dag.py
[2024-09-02T21:46:59.546+0000] {processor.py:830} INFO - Processing file /opt/airflow/dags/etl_dag.py for tasks to queue
[2024-09-02T21:46:59.548+0000] {logging_mixin.py:188} INFO - [2024-09-02T21:46:59.548+0000] {dagbag.py:545} INFO - Filling up the DagBag from /opt/airflow/dags/etl_dag.py
[2024-09-02T21:47:00.115+0000] {logging_mixin.py:188} INFO - [2024-09-02T21:47:00.108+0000] {dagbag.py:355} ERROR - Failed to import: /opt/airflow/dags/etl_dag.py
Traceback (most recent call last):
  File "/home/airflow/.local/lib/python3.12/site-packages/airflow/models/dagbag.py", line 351, in parse
    loader.exec_module(new_module)
  File "<frozen importlib._bootstrap_external>", line 995, in exec_module
  File "<frozen importlib._bootstrap>", line 488, in _call_with_frames_removed
  File "/opt/airflow/dags/etl_dag.py", line 21, in <module>
    with DAG(
         ^^^^
  File "/home/airflow/.local/lib/python3.12/site-packages/airflow/models/dag.py", line 543, in __init__
    if start_date and start_date.tzinfo:
                      ^^^^^^^^^^^^^^^^^
AttributeError: 'datetime.date' object has no attribute 'tzinfo'
[2024-09-02T21:47:00.117+0000] {processor.py:842} WARNING - No viable dags retrieved from /opt/airflow/dags/etl_dag.py
[2024-09-02T21:47:00.136+0000] {processor.py:183} INFO - Processing /opt/airflow/dags/etl_dag.py took 0.596 seconds
[2024-09-02T21:47:14.647+0000] {processor.py:161} INFO - Started process (PID=419) to work on /opt/airflow/dags/etl_dag.py
[2024-09-02T21:47:14.649+0000] {processor.py:830} INFO - Processing file /opt/airflow/dags/etl_dag.py for tasks to queue
[2024-09-02T21:47:14.651+0000] {logging_mixin.py:188} INFO - [2024-09-02T21:47:14.651+0000] {dagbag.py:545} INFO - Filling up the DagBag from /opt/airflow/dags/etl_dag.py
[2024-09-02T21:47:15.266+0000] {logging_mixin.py:188} INFO - [2024-09-02T21:47:15.258+0000] {dagbag.py:355} ERROR - Failed to import: /opt/airflow/dags/etl_dag.py
Traceback (most recent call last):
  File "/home/airflow/.local/lib/python3.12/site-packages/airflow/models/dagbag.py", line 351, in parse
    loader.exec_module(new_module)
  File "<frozen importlib._bootstrap_external>", line 995, in exec_module
  File "<frozen importlib._bootstrap>", line 488, in _call_with_frames_removed
  File "/opt/airflow/dags/etl_dag.py", line 21, in <module>
    with DAG(
         ^^^^
  File "/home/airflow/.local/lib/python3.12/site-packages/airflow/models/dag.py", line 543, in __init__
    if start_date and start_date.tzinfo:
                      ^^^^^^^^^^^^^^^^^
AttributeError: 'datetime.date' object has no attribute 'tzinfo'
[2024-09-02T21:47:15.269+0000] {processor.py:842} WARNING - No viable dags retrieved from /opt/airflow/dags/etl_dag.py
[2024-09-02T21:47:15.285+0000] {processor.py:183} INFO - Processing /opt/airflow/dags/etl_dag.py took 0.646 seconds
[2024-09-02T21:47:46.189+0000] {processor.py:161} INFO - Started process (PID=481) to work on /opt/airflow/dags/etl_dag.py
[2024-09-02T21:47:46.191+0000] {processor.py:830} INFO - Processing file /opt/airflow/dags/etl_dag.py for tasks to queue
[2024-09-02T21:47:46.195+0000] {logging_mixin.py:188} INFO - [2024-09-02T21:47:46.194+0000] {dagbag.py:545} INFO - Filling up the DagBag from /opt/airflow/dags/etl_dag.py
[2024-09-02T21:47:46.997+0000] {logging_mixin.py:188} INFO - [2024-09-02T21:47:46.979+0000] {dagbag.py:355} ERROR - Failed to import: /opt/airflow/dags/etl_dag.py
Traceback (most recent call last):
  File "/home/airflow/.local/lib/python3.12/site-packages/airflow/models/dagbag.py", line 351, in parse
    loader.exec_module(new_module)
  File "<frozen importlib._bootstrap_external>", line 995, in exec_module
  File "<frozen importlib._bootstrap>", line 488, in _call_with_frames_removed
  File "/opt/airflow/dags/etl_dag.py", line 21, in <module>
    with DAG(
         ^^^^
  File "/home/airflow/.local/lib/python3.12/site-packages/airflow/models/dag.py", line 543, in __init__
    if start_date and start_date.tzinfo:
                      ^^^^^^^^^^^^^^^^^
AttributeError: 'datetime.date' object has no attribute 'tzinfo'
[2024-09-02T21:47:47.001+0000] {processor.py:842} WARNING - No viable dags retrieved from /opt/airflow/dags/etl_dag.py
[2024-09-02T21:47:47.029+0000] {processor.py:183} INFO - Processing /opt/airflow/dags/etl_dag.py took 0.852 seconds
[2024-09-02T21:48:17.994+0000] {processor.py:161} INFO - Started process (PID=547) to work on /opt/airflow/dags/etl_dag.py
[2024-09-02T21:48:17.995+0000] {processor.py:830} INFO - Processing file /opt/airflow/dags/etl_dag.py for tasks to queue
[2024-09-02T21:48:17.999+0000] {logging_mixin.py:188} INFO - [2024-09-02T21:48:17.998+0000] {dagbag.py:545} INFO - Filling up the DagBag from /opt/airflow/dags/etl_dag.py
[2024-09-02T21:48:18.936+0000] {logging_mixin.py:188} INFO - [2024-09-02T21:48:18.926+0000] {dagbag.py:355} ERROR - Failed to import: /opt/airflow/dags/etl_dag.py
Traceback (most recent call last):
  File "/home/airflow/.local/lib/python3.12/site-packages/airflow/models/dagbag.py", line 351, in parse
    loader.exec_module(new_module)
  File "<frozen importlib._bootstrap_external>", line 995, in exec_module
  File "<frozen importlib._bootstrap>", line 488, in _call_with_frames_removed
  File "/opt/airflow/dags/etl_dag.py", line 21, in <module>
    with DAG(
         ^^^^
  File "/home/airflow/.local/lib/python3.12/site-packages/airflow/models/dag.py", line 543, in __init__
    if start_date and start_date.tzinfo:
                      ^^^^^^^^^^^^^^^^^
AttributeError: 'datetime.date' object has no attribute 'tzinfo'
[2024-09-02T21:48:18.945+0000] {processor.py:842} WARNING - No viable dags retrieved from /opt/airflow/dags/etl_dag.py
[2024-09-02T21:48:18.972+0000] {processor.py:183} INFO - Processing /opt/airflow/dags/etl_dag.py took 0.991 seconds
[2024-09-02T21:48:49.411+0000] {processor.py:161} INFO - Started process (PID=607) to work on /opt/airflow/dags/etl_dag.py
[2024-09-02T21:48:49.413+0000] {processor.py:830} INFO - Processing file /opt/airflow/dags/etl_dag.py for tasks to queue
[2024-09-02T21:48:49.415+0000] {logging_mixin.py:188} INFO - [2024-09-02T21:48:49.415+0000] {dagbag.py:545} INFO - Filling up the DagBag from /opt/airflow/dags/etl_dag.py
[2024-09-02T21:48:50.066+0000] {logging_mixin.py:188} INFO - [2024-09-02T21:48:50.053+0000] {dagbag.py:355} ERROR - Failed to import: /opt/airflow/dags/etl_dag.py
Traceback (most recent call last):
  File "/home/airflow/.local/lib/python3.12/site-packages/airflow/models/dagbag.py", line 351, in parse
    loader.exec_module(new_module)
  File "<frozen importlib._bootstrap_external>", line 995, in exec_module
  File "<frozen importlib._bootstrap>", line 488, in _call_with_frames_removed
  File "/opt/airflow/dags/etl_dag.py", line 21, in <module>
    with DAG(
         ^^^^
  File "/home/airflow/.local/lib/python3.12/site-packages/airflow/models/dag.py", line 543, in __init__
    if start_date and start_date.tzinfo:
                      ^^^^^^^^^^^^^^^^^
AttributeError: 'datetime.date' object has no attribute 'tzinfo'
[2024-09-02T21:48:50.070+0000] {processor.py:842} WARNING - No viable dags retrieved from /opt/airflow/dags/etl_dag.py
[2024-09-02T21:48:50.096+0000] {processor.py:183} INFO - Processing /opt/airflow/dags/etl_dag.py took 0.695 seconds
[2024-09-02T21:49:20.794+0000] {processor.py:161} INFO - Started process (PID=667) to work on /opt/airflow/dags/etl_dag.py
[2024-09-02T21:49:20.796+0000] {processor.py:830} INFO - Processing file /opt/airflow/dags/etl_dag.py for tasks to queue
[2024-09-02T21:49:20.801+0000] {logging_mixin.py:188} INFO - [2024-09-02T21:49:20.800+0000] {dagbag.py:545} INFO - Filling up the DagBag from /opt/airflow/dags/etl_dag.py
[2024-09-02T21:49:21.799+0000] {logging_mixin.py:188} INFO - [2024-09-02T21:49:21.791+0000] {dagbag.py:355} ERROR - Failed to import: /opt/airflow/dags/etl_dag.py
Traceback (most recent call last):
  File "/home/airflow/.local/lib/python3.12/site-packages/airflow/models/dagbag.py", line 351, in parse
    loader.exec_module(new_module)
  File "<frozen importlib._bootstrap_external>", line 995, in exec_module
  File "<frozen importlib._bootstrap>", line 488, in _call_with_frames_removed
  File "/opt/airflow/dags/etl_dag.py", line 21, in <module>
    with DAG(
         ^^^^
  File "/home/airflow/.local/lib/python3.12/site-packages/airflow/models/dag.py", line 543, in __init__
    if start_date and start_date.tzinfo:
                      ^^^^^^^^^^^^^^^^^
AttributeError: 'datetime.date' object has no attribute 'tzinfo'
[2024-09-02T21:49:21.802+0000] {processor.py:842} WARNING - No viable dags retrieved from /opt/airflow/dags/etl_dag.py
[2024-09-02T21:49:21.826+0000] {processor.py:183} INFO - Processing /opt/airflow/dags/etl_dag.py took 1.051 seconds
[2024-09-02T21:49:52.005+0000] {processor.py:161} INFO - Started process (PID=727) to work on /opt/airflow/dags/etl_dag.py
[2024-09-02T21:49:52.007+0000] {processor.py:830} INFO - Processing file /opt/airflow/dags/etl_dag.py for tasks to queue
[2024-09-02T21:49:52.009+0000] {logging_mixin.py:188} INFO - [2024-09-02T21:49:52.009+0000] {dagbag.py:545} INFO - Filling up the DagBag from /opt/airflow/dags/etl_dag.py
[2024-09-02T21:49:52.669+0000] {logging_mixin.py:188} INFO - [2024-09-02T21:49:52.658+0000] {dagbag.py:355} ERROR - Failed to import: /opt/airflow/dags/etl_dag.py
Traceback (most recent call last):
  File "/home/airflow/.local/lib/python3.12/site-packages/airflow/models/dagbag.py", line 351, in parse
    loader.exec_module(new_module)
  File "<frozen importlib._bootstrap_external>", line 995, in exec_module
  File "<frozen importlib._bootstrap>", line 488, in _call_with_frames_removed
  File "/opt/airflow/dags/etl_dag.py", line 21, in <module>
    with DAG(
         ^^^^
  File "/home/airflow/.local/lib/python3.12/site-packages/airflow/models/dag.py", line 543, in __init__
    if start_date and start_date.tzinfo:
                      ^^^^^^^^^^^^^^^^^
AttributeError: 'datetime.date' object has no attribute 'tzinfo'
[2024-09-02T21:49:52.673+0000] {processor.py:842} WARNING - No viable dags retrieved from /opt/airflow/dags/etl_dag.py
[2024-09-02T21:49:52.703+0000] {processor.py:183} INFO - Processing /opt/airflow/dags/etl_dag.py took 0.706 seconds
[2024-09-02T21:50:23.619+0000] {processor.py:161} INFO - Started process (PID=787) to work on /opt/airflow/dags/etl_dag.py
[2024-09-02T21:50:23.620+0000] {processor.py:830} INFO - Processing file /opt/airflow/dags/etl_dag.py for tasks to queue
[2024-09-02T21:50:23.622+0000] {logging_mixin.py:188} INFO - [2024-09-02T21:50:23.621+0000] {dagbag.py:545} INFO - Filling up the DagBag from /opt/airflow/dags/etl_dag.py
[2024-09-02T21:50:24.408+0000] {logging_mixin.py:188} INFO - [2024-09-02T21:50:24.400+0000] {dagbag.py:355} ERROR - Failed to import: /opt/airflow/dags/etl_dag.py
Traceback (most recent call last):
  File "/home/airflow/.local/lib/python3.12/site-packages/airflow/models/dagbag.py", line 351, in parse
    loader.exec_module(new_module)
  File "<frozen importlib._bootstrap_external>", line 995, in exec_module
  File "<frozen importlib._bootstrap>", line 488, in _call_with_frames_removed
  File "/opt/airflow/dags/etl_dag.py", line 21, in <module>
    with DAG(
         ^^^^
  File "/home/airflow/.local/lib/python3.12/site-packages/airflow/models/dag.py", line 543, in __init__
    if start_date and start_date.tzinfo:
                      ^^^^^^^^^^^^^^^^^
AttributeError: 'datetime.date' object has no attribute 'tzinfo'
[2024-09-02T21:50:24.411+0000] {processor.py:842} WARNING - No viable dags retrieved from /opt/airflow/dags/etl_dag.py
[2024-09-02T21:50:24.429+0000] {processor.py:183} INFO - Processing /opt/airflow/dags/etl_dag.py took 0.817 seconds
[2024-09-02T21:50:54.918+0000] {processor.py:161} INFO - Started process (PID=847) to work on /opt/airflow/dags/etl_dag.py
[2024-09-02T21:50:54.919+0000] {processor.py:830} INFO - Processing file /opt/airflow/dags/etl_dag.py for tasks to queue
[2024-09-02T21:50:54.921+0000] {logging_mixin.py:188} INFO - [2024-09-02T21:50:54.920+0000] {dagbag.py:545} INFO - Filling up the DagBag from /opt/airflow/dags/etl_dag.py
[2024-09-02T21:50:55.486+0000] {logging_mixin.py:188} INFO - [2024-09-02T21:50:55.480+0000] {dagbag.py:355} ERROR - Failed to import: /opt/airflow/dags/etl_dag.py
Traceback (most recent call last):
  File "/home/airflow/.local/lib/python3.12/site-packages/airflow/models/dagbag.py", line 351, in parse
    loader.exec_module(new_module)
  File "<frozen importlib._bootstrap_external>", line 995, in exec_module
  File "<frozen importlib._bootstrap>", line 488, in _call_with_frames_removed
  File "/opt/airflow/dags/etl_dag.py", line 21, in <module>
    with DAG(
         ^^^^
  File "/home/airflow/.local/lib/python3.12/site-packages/airflow/models/dag.py", line 543, in __init__
    if start_date and start_date.tzinfo:
                      ^^^^^^^^^^^^^^^^^
AttributeError: 'datetime.date' object has no attribute 'tzinfo'
[2024-09-02T21:50:55.489+0000] {processor.py:842} WARNING - No viable dags retrieved from /opt/airflow/dags/etl_dag.py
[2024-09-02T21:50:55.516+0000] {processor.py:183} INFO - Processing /opt/airflow/dags/etl_dag.py took 0.603 seconds
[2024-09-02T21:51:26.155+0000] {processor.py:161} INFO - Started process (PID=907) to work on /opt/airflow/dags/etl_dag.py
[2024-09-02T21:51:26.156+0000] {processor.py:830} INFO - Processing file /opt/airflow/dags/etl_dag.py for tasks to queue
[2024-09-02T21:51:26.159+0000] {logging_mixin.py:188} INFO - [2024-09-02T21:51:26.158+0000] {dagbag.py:545} INFO - Filling up the DagBag from /opt/airflow/dags/etl_dag.py
[2024-09-02T21:51:26.697+0000] {logging_mixin.py:188} INFO - [2024-09-02T21:51:26.688+0000] {dagbag.py:355} ERROR - Failed to import: /opt/airflow/dags/etl_dag.py
Traceback (most recent call last):
  File "/home/airflow/.local/lib/python3.12/site-packages/airflow/models/dagbag.py", line 351, in parse
    loader.exec_module(new_module)
  File "<frozen importlib._bootstrap_external>", line 995, in exec_module
  File "<frozen importlib._bootstrap>", line 488, in _call_with_frames_removed
  File "/opt/airflow/dags/etl_dag.py", line 21, in <module>
    with DAG(
         ^^^^
  File "/home/airflow/.local/lib/python3.12/site-packages/airflow/models/dag.py", line 543, in __init__
    if start_date and start_date.tzinfo:
                      ^^^^^^^^^^^^^^^^^
AttributeError: 'datetime.date' object has no attribute 'tzinfo'
[2024-09-02T21:51:26.700+0000] {processor.py:842} WARNING - No viable dags retrieved from /opt/airflow/dags/etl_dag.py
[2024-09-02T21:51:26.719+0000] {processor.py:183} INFO - Processing /opt/airflow/dags/etl_dag.py took 0.570 seconds
[2024-09-02T21:51:57.197+0000] {processor.py:161} INFO - Started process (PID=967) to work on /opt/airflow/dags/etl_dag.py
[2024-09-02T21:51:57.198+0000] {processor.py:830} INFO - Processing file /opt/airflow/dags/etl_dag.py for tasks to queue
[2024-09-02T21:51:57.202+0000] {logging_mixin.py:188} INFO - [2024-09-02T21:51:57.201+0000] {dagbag.py:545} INFO - Filling up the DagBag from /opt/airflow/dags/etl_dag.py
[2024-09-02T21:51:57.801+0000] {logging_mixin.py:188} INFO - [2024-09-02T21:51:57.793+0000] {dagbag.py:355} ERROR - Failed to import: /opt/airflow/dags/etl_dag.py
Traceback (most recent call last):
  File "/home/airflow/.local/lib/python3.12/site-packages/airflow/models/dagbag.py", line 351, in parse
    loader.exec_module(new_module)
  File "<frozen importlib._bootstrap_external>", line 995, in exec_module
  File "<frozen importlib._bootstrap>", line 488, in _call_with_frames_removed
  File "/opt/airflow/dags/etl_dag.py", line 21, in <module>
    with DAG(
         ^^^^
  File "/home/airflow/.local/lib/python3.12/site-packages/airflow/models/dag.py", line 543, in __init__
    if start_date and start_date.tzinfo:
                      ^^^^^^^^^^^^^^^^^
AttributeError: 'datetime.date' object has no attribute 'tzinfo'
[2024-09-02T21:51:57.804+0000] {processor.py:842} WARNING - No viable dags retrieved from /opt/airflow/dags/etl_dag.py
[2024-09-02T21:51:57.818+0000] {processor.py:183} INFO - Processing /opt/airflow/dags/etl_dag.py took 0.630 seconds
[2024-09-02T21:52:28.783+0000] {processor.py:161} INFO - Started process (PID=1027) to work on /opt/airflow/dags/etl_dag.py
[2024-09-02T21:52:28.784+0000] {processor.py:830} INFO - Processing file /opt/airflow/dags/etl_dag.py for tasks to queue
[2024-09-02T21:52:28.786+0000] {logging_mixin.py:188} INFO - [2024-09-02T21:52:28.785+0000] {dagbag.py:545} INFO - Filling up the DagBag from /opt/airflow/dags/etl_dag.py
[2024-09-02T21:52:29.283+0000] {logging_mixin.py:188} INFO - [2024-09-02T21:52:29.272+0000] {dagbag.py:355} ERROR - Failed to import: /opt/airflow/dags/etl_dag.py
Traceback (most recent call last):
  File "/home/airflow/.local/lib/python3.12/site-packages/airflow/models/dagbag.py", line 351, in parse
    loader.exec_module(new_module)
  File "<frozen importlib._bootstrap_external>", line 995, in exec_module
  File "<frozen importlib._bootstrap>", line 488, in _call_with_frames_removed
  File "/opt/airflow/dags/etl_dag.py", line 21, in <module>
    with DAG(
         ^^^^
  File "/home/airflow/.local/lib/python3.12/site-packages/airflow/models/dag.py", line 543, in __init__
    if start_date and start_date.tzinfo:
                      ^^^^^^^^^^^^^^^^^
AttributeError: 'datetime.date' object has no attribute 'tzinfo'
[2024-09-02T21:52:29.286+0000] {processor.py:842} WARNING - No viable dags retrieved from /opt/airflow/dags/etl_dag.py
[2024-09-02T21:52:29.303+0000] {processor.py:183} INFO - Processing /opt/airflow/dags/etl_dag.py took 0.527 seconds
[2024-09-02T21:53:00.198+0000] {processor.py:161} INFO - Started process (PID=1087) to work on /opt/airflow/dags/etl_dag.py
[2024-09-02T21:53:00.199+0000] {processor.py:830} INFO - Processing file /opt/airflow/dags/etl_dag.py for tasks to queue
[2024-09-02T21:53:00.201+0000] {logging_mixin.py:188} INFO - [2024-09-02T21:53:00.200+0000] {dagbag.py:545} INFO - Filling up the DagBag from /opt/airflow/dags/etl_dag.py
[2024-09-02T21:53:00.706+0000] {logging_mixin.py:188} INFO - [2024-09-02T21:53:00.696+0000] {dagbag.py:355} ERROR - Failed to import: /opt/airflow/dags/etl_dag.py
Traceback (most recent call last):
  File "/home/airflow/.local/lib/python3.12/site-packages/airflow/models/dagbag.py", line 351, in parse
    loader.exec_module(new_module)
  File "<frozen importlib._bootstrap_external>", line 995, in exec_module
  File "<frozen importlib._bootstrap>", line 488, in _call_with_frames_removed
  File "/opt/airflow/dags/etl_dag.py", line 21, in <module>
    with DAG(
         ^^^^
  File "/home/airflow/.local/lib/python3.12/site-packages/airflow/models/dag.py", line 543, in __init__
    if start_date and start_date.tzinfo:
                      ^^^^^^^^^^^^^^^^^
AttributeError: 'datetime.date' object has no attribute 'tzinfo'
[2024-09-02T21:53:00.710+0000] {processor.py:842} WARNING - No viable dags retrieved from /opt/airflow/dags/etl_dag.py
[2024-09-02T21:53:00.729+0000] {processor.py:183} INFO - Processing /opt/airflow/dags/etl_dag.py took 0.537 seconds
[2024-09-02T21:53:31.467+0000] {processor.py:161} INFO - Started process (PID=1147) to work on /opt/airflow/dags/etl_dag.py
[2024-09-02T21:53:31.468+0000] {processor.py:830} INFO - Processing file /opt/airflow/dags/etl_dag.py for tasks to queue
[2024-09-02T21:53:31.470+0000] {logging_mixin.py:188} INFO - [2024-09-02T21:53:31.469+0000] {dagbag.py:545} INFO - Filling up the DagBag from /opt/airflow/dags/etl_dag.py
[2024-09-02T21:53:31.952+0000] {logging_mixin.py:188} INFO - [2024-09-02T21:53:31.946+0000] {dagbag.py:355} ERROR - Failed to import: /opt/airflow/dags/etl_dag.py
Traceback (most recent call last):
  File "/home/airflow/.local/lib/python3.12/site-packages/airflow/models/dagbag.py", line 351, in parse
    loader.exec_module(new_module)
  File "<frozen importlib._bootstrap_external>", line 995, in exec_module
  File "<frozen importlib._bootstrap>", line 488, in _call_with_frames_removed
  File "/opt/airflow/dags/etl_dag.py", line 21, in <module>
    with DAG(
         ^^^^
  File "/home/airflow/.local/lib/python3.12/site-packages/airflow/models/dag.py", line 543, in __init__
    if start_date and start_date.tzinfo:
                      ^^^^^^^^^^^^^^^^^
AttributeError: 'datetime.date' object has no attribute 'tzinfo'
[2024-09-02T21:53:31.955+0000] {processor.py:842} WARNING - No viable dags retrieved from /opt/airflow/dags/etl_dag.py
[2024-09-02T21:53:31.985+0000] {processor.py:183} INFO - Processing /opt/airflow/dags/etl_dag.py took 0.523 seconds
[2024-09-02T21:54:02.371+0000] {processor.py:161} INFO - Started process (PID=1208) to work on /opt/airflow/dags/etl_dag.py
[2024-09-02T21:54:02.372+0000] {processor.py:830} INFO - Processing file /opt/airflow/dags/etl_dag.py for tasks to queue
[2024-09-02T21:54:02.375+0000] {logging_mixin.py:188} INFO - [2024-09-02T21:54:02.375+0000] {dagbag.py:545} INFO - Filling up the DagBag from /opt/airflow/dags/etl_dag.py
[2024-09-02T21:54:03.043+0000] {logging_mixin.py:188} INFO - [2024-09-02T21:54:03.034+0000] {dagbag.py:355} ERROR - Failed to import: /opt/airflow/dags/etl_dag.py
Traceback (most recent call last):
  File "/home/airflow/.local/lib/python3.12/site-packages/airflow/models/dagbag.py", line 351, in parse
    loader.exec_module(new_module)
  File "<frozen importlib._bootstrap_external>", line 995, in exec_module
  File "<frozen importlib._bootstrap>", line 488, in _call_with_frames_removed
  File "/opt/airflow/dags/etl_dag.py", line 21, in <module>
    with DAG(
         ^^^^
  File "/home/airflow/.local/lib/python3.12/site-packages/airflow/models/dag.py", line 543, in __init__
    if start_date and start_date.tzinfo:
                      ^^^^^^^^^^^^^^^^^
AttributeError: 'datetime.date' object has no attribute 'tzinfo'
[2024-09-02T21:54:03.046+0000] {processor.py:842} WARNING - No viable dags retrieved from /opt/airflow/dags/etl_dag.py
[2024-09-02T21:54:03.065+0000] {processor.py:183} INFO - Processing /opt/airflow/dags/etl_dag.py took 0.703 seconds
[2024-09-02T21:54:33.483+0000] {processor.py:161} INFO - Started process (PID=1268) to work on /opt/airflow/dags/etl_dag.py
[2024-09-02T21:54:33.484+0000] {processor.py:830} INFO - Processing file /opt/airflow/dags/etl_dag.py for tasks to queue
[2024-09-02T21:54:33.486+0000] {logging_mixin.py:188} INFO - [2024-09-02T21:54:33.486+0000] {dagbag.py:545} INFO - Filling up the DagBag from /opt/airflow/dags/etl_dag.py
[2024-09-02T21:54:34.080+0000] {logging_mixin.py:188} INFO - [2024-09-02T21:54:34.071+0000] {dagbag.py:355} ERROR - Failed to import: /opt/airflow/dags/etl_dag.py
Traceback (most recent call last):
  File "/home/airflow/.local/lib/python3.12/site-packages/airflow/models/dagbag.py", line 351, in parse
    loader.exec_module(new_module)
  File "<frozen importlib._bootstrap_external>", line 995, in exec_module
  File "<frozen importlib._bootstrap>", line 488, in _call_with_frames_removed
  File "/opt/airflow/dags/etl_dag.py", line 21, in <module>
    with DAG(
         ^^^^
  File "/home/airflow/.local/lib/python3.12/site-packages/airflow/models/dag.py", line 543, in __init__
    if start_date and start_date.tzinfo:
                      ^^^^^^^^^^^^^^^^^
AttributeError: 'datetime.date' object has no attribute 'tzinfo'
[2024-09-02T21:54:34.084+0000] {processor.py:842} WARNING - No viable dags retrieved from /opt/airflow/dags/etl_dag.py
[2024-09-02T21:54:34.118+0000] {processor.py:183} INFO - Processing /opt/airflow/dags/etl_dag.py took 0.641 seconds
[2024-09-02T21:55:04.968+0000] {processor.py:161} INFO - Started process (PID=1328) to work on /opt/airflow/dags/etl_dag.py
[2024-09-02T21:55:04.969+0000] {processor.py:830} INFO - Processing file /opt/airflow/dags/etl_dag.py for tasks to queue
[2024-09-02T21:55:04.971+0000] {logging_mixin.py:188} INFO - [2024-09-02T21:55:04.971+0000] {dagbag.py:545} INFO - Filling up the DagBag from /opt/airflow/dags/etl_dag.py
[2024-09-02T21:55:05.466+0000] {logging_mixin.py:188} INFO - [2024-09-02T21:55:05.458+0000] {dagbag.py:355} ERROR - Failed to import: /opt/airflow/dags/etl_dag.py
Traceback (most recent call last):
  File "/home/airflow/.local/lib/python3.12/site-packages/airflow/models/dagbag.py", line 351, in parse
    loader.exec_module(new_module)
  File "<frozen importlib._bootstrap_external>", line 995, in exec_module
  File "<frozen importlib._bootstrap>", line 488, in _call_with_frames_removed
  File "/opt/airflow/dags/etl_dag.py", line 21, in <module>
    with DAG(
         ^^^^
  File "/home/airflow/.local/lib/python3.12/site-packages/airflow/models/dag.py", line 543, in __init__
    if start_date and start_date.tzinfo:
                      ^^^^^^^^^^^^^^^^^
AttributeError: 'datetime.date' object has no attribute 'tzinfo'
[2024-09-02T21:55:05.468+0000] {processor.py:842} WARNING - No viable dags retrieved from /opt/airflow/dags/etl_dag.py
[2024-09-02T21:55:05.483+0000] {processor.py:183} INFO - Processing /opt/airflow/dags/etl_dag.py took 0.521 seconds
[2024-09-02T21:55:13.520+0000] {processor.py:161} INFO - Started process (PID=1343) to work on /opt/airflow/dags/etl_dag.py
[2024-09-02T21:55:13.521+0000] {processor.py:830} INFO - Processing file /opt/airflow/dags/etl_dag.py for tasks to queue
[2024-09-02T21:55:13.523+0000] {logging_mixin.py:188} INFO - [2024-09-02T21:55:13.523+0000] {dagbag.py:545} INFO - Filling up the DagBag from /opt/airflow/dags/etl_dag.py
[2024-09-02T21:55:13.995+0000] {logging_mixin.py:188} INFO - [2024-09-02T21:55:13.988+0000] {dagbag.py:355} ERROR - Failed to import: /opt/airflow/dags/etl_dag.py
Traceback (most recent call last):
  File "/home/airflow/.local/lib/python3.12/site-packages/airflow/models/dagbag.py", line 351, in parse
    loader.exec_module(new_module)
  File "<frozen importlib._bootstrap_external>", line 995, in exec_module
  File "<frozen importlib._bootstrap>", line 488, in _call_with_frames_removed
  File "/opt/airflow/dags/etl_dag.py", line 21, in <module>
    with DAG(
         ^^^^
  File "/home/airflow/.local/lib/python3.12/site-packages/airflow/models/dag.py", line 543, in __init__
    if start_date and start_date.tzinfo:
                      ^^^^^^^^^^^^^^^^^
AttributeError: 'datetime.date' object has no attribute 'tzinfo'
[2024-09-02T21:55:13.998+0000] {processor.py:842} WARNING - No viable dags retrieved from /opt/airflow/dags/etl_dag.py
[2024-09-02T21:55:14.012+0000] {processor.py:183} INFO - Processing /opt/airflow/dags/etl_dag.py took 0.497 seconds
[2024-09-02T21:55:19.014+0000] {processor.py:161} INFO - Started process (PID=1358) to work on /opt/airflow/dags/etl_dag.py
[2024-09-02T21:55:19.016+0000] {processor.py:830} INFO - Processing file /opt/airflow/dags/etl_dag.py for tasks to queue
[2024-09-02T21:55:19.019+0000] {logging_mixin.py:188} INFO - [2024-09-02T21:55:19.018+0000] {dagbag.py:545} INFO - Filling up the DagBag from /opt/airflow/dags/etl_dag.py
[2024-09-02T21:55:19.629+0000] {logging_mixin.py:188} INFO - [2024-09-02T21:55:19.621+0000] {dagbag.py:355} ERROR - Failed to import: /opt/airflow/dags/etl_dag.py
Traceback (most recent call last):
  File "/home/airflow/.local/lib/python3.12/site-packages/airflow/models/dagbag.py", line 351, in parse
    loader.exec_module(new_module)
  File "<frozen importlib._bootstrap_external>", line 995, in exec_module
  File "<frozen importlib._bootstrap>", line 488, in _call_with_frames_removed
  File "/opt/airflow/dags/etl_dag.py", line 21, in <module>
    with DAG(
         ^^^^
  File "/home/airflow/.local/lib/python3.12/site-packages/airflow/models/dag.py", line 543, in __init__
    if start_date and start_date.tzinfo:
                      ^^^^^^^^^^^^^^^^^
AttributeError: 'datetime.date' object has no attribute 'tzinfo'
[2024-09-02T21:55:19.633+0000] {processor.py:842} WARNING - No viable dags retrieved from /opt/airflow/dags/etl_dag.py
[2024-09-02T21:55:19.652+0000] {processor.py:183} INFO - Processing /opt/airflow/dags/etl_dag.py took 0.646 seconds
[2024-09-02T21:55:41.632+0000] {processor.py:161} INFO - Started process (PID=1394) to work on /opt/airflow/dags/etl_dag.py
[2024-09-02T21:55:41.633+0000] {processor.py:830} INFO - Processing file /opt/airflow/dags/etl_dag.py for tasks to queue
[2024-09-02T21:55:41.636+0000] {logging_mixin.py:188} INFO - [2024-09-02T21:55:41.635+0000] {dagbag.py:545} INFO - Filling up the DagBag from /opt/airflow/dags/etl_dag.py
[2024-09-02T21:55:42.552+0000] {processor.py:840} INFO - DAG(s) 'solar_adoption_dag' retrieved from /opt/airflow/dags/etl_dag.py
[2024-09-02T21:55:42.836+0000] {logging_mixin.py:188} INFO - [2024-09-02T21:55:42.834+0000] {override.py:1829} INFO - Created Permission View: can read on DAG:solar_adoption_dag
[2024-09-02T21:55:42.857+0000] {logging_mixin.py:188} INFO - [2024-09-02T21:55:42.856+0000] {override.py:1829} INFO - Created Permission View: can delete on DAG:solar_adoption_dag
[2024-09-02T21:55:42.868+0000] {logging_mixin.py:188} INFO - [2024-09-02T21:55:42.868+0000] {override.py:1829} INFO - Created Permission View: can edit on DAG:solar_adoption_dag
[2024-09-02T21:55:42.869+0000] {logging_mixin.py:188} INFO - [2024-09-02T21:55:42.869+0000] {dag.py:3096} INFO - Sync 1 DAGs
[2024-09-02T21:55:42.888+0000] {logging_mixin.py:188} INFO - [2024-09-02T21:55:42.887+0000] {dag.py:3118} INFO - Creating ORM DAG for solar_adoption_dag
[2024-09-02T21:55:42.909+0000] {logging_mixin.py:188} INFO - [2024-09-02T21:55:42.908+0000] {dag.py:3954} INFO - Setting next_dagrun for solar_adoption_dag to 2024-07-08 00:00:00+00:00, run_after=2024-07-09 00:00:00+00:00
[2024-09-02T21:55:42.933+0000] {processor.py:183} INFO - Processing /opt/airflow/dags/etl_dag.py took 1.309 seconds
[2024-09-02T21:55:45.629+0000] {processor.py:161} INFO - Started process (PID=1409) to work on /opt/airflow/dags/etl_dag.py
[2024-09-02T21:55:45.630+0000] {processor.py:830} INFO - Processing file /opt/airflow/dags/etl_dag.py for tasks to queue
[2024-09-02T21:55:45.632+0000] {logging_mixin.py:188} INFO - [2024-09-02T21:55:45.632+0000] {dagbag.py:545} INFO - Filling up the DagBag from /opt/airflow/dags/etl_dag.py
[2024-09-02T21:55:46.290+0000] {processor.py:840} INFO - DAG(s) 'solar_adoption_dag' retrieved from /opt/airflow/dags/etl_dag.py
[2024-09-02T21:55:46.305+0000] {logging_mixin.py:188} INFO - [2024-09-02T21:55:46.304+0000] {dag.py:3096} INFO - Sync 1 DAGs
[2024-09-02T21:55:46.334+0000] {logging_mixin.py:188} INFO - [2024-09-02T21:55:46.334+0000] {dag.py:3954} INFO - Setting next_dagrun for solar_adoption_dag to 2024-09-02 00:00:00+00:00, run_after=2024-09-03 00:00:00+00:00
[2024-09-02T21:55:46.360+0000] {processor.py:183} INFO - Processing /opt/airflow/dags/etl_dag.py took 0.741 seconds
[2024-09-02T21:56:05.606+0000] {processor.py:161} INFO - Started process (PID=1455) to work on /opt/airflow/dags/etl_dag.py
[2024-09-02T21:56:05.608+0000] {processor.py:830} INFO - Processing file /opt/airflow/dags/etl_dag.py for tasks to queue
[2024-09-02T21:56:05.612+0000] {logging_mixin.py:188} INFO - [2024-09-02T21:56:05.611+0000] {dagbag.py:545} INFO - Filling up the DagBag from /opt/airflow/dags/etl_dag.py
[2024-09-02T21:56:06.742+0000] {processor.py:840} INFO - DAG(s) 'solar_adoption_dag' retrieved from /opt/airflow/dags/etl_dag.py
[2024-09-02T21:56:06.767+0000] {logging_mixin.py:188} INFO - [2024-09-02T21:56:06.766+0000] {dag.py:3096} INFO - Sync 1 DAGs
[2024-09-02T21:56:06.810+0000] {logging_mixin.py:188} INFO - [2024-09-02T21:56:06.809+0000] {dag.py:3954} INFO - Setting next_dagrun for solar_adoption_dag to 2024-09-02 00:00:00+00:00, run_after=2024-09-03 00:00:00+00:00
[2024-09-02T21:56:06.861+0000] {processor.py:183} INFO - Processing /opt/airflow/dags/etl_dag.py took 1.264 seconds
