[2024-09-03T17:59:34.608+0000] {local_task_job_runner.py:120} INFO - ::group::Pre task execution logs
[2024-09-03T17:59:34.801+0000] {taskinstance.py:2076} INFO - Dependencies all met for dep_context=non-requeueable deps ti=<TaskInstance: solar_adoption_dag.load_TractRecords__fct manual__2024-09-03T17:59:06.450178+00:00 [queued]>
[2024-09-03T17:59:34.868+0000] {taskinstance.py:2076} INFO - Dependencies all met for dep_context=requeueable deps ti=<TaskInstance: solar_adoption_dag.load_TractRecords__fct manual__2024-09-03T17:59:06.450178+00:00 [queued]>
[2024-09-03T17:59:34.873+0000] {taskinstance.py:2306} INFO - Starting attempt 1 of 1
[2024-09-03T17:59:35.024+0000] {taskinstance.py:2330} INFO - Executing <Task(PythonOperator): load_TractRecords__fct> on 2024-09-03 17:59:06.450178+00:00
[2024-09-03T17:59:35.046+0000] {warnings.py:112} WARNING - /home/***/.local/lib/python3.12/site-packages/***/task/task_runner/standard_task_runner.py:61: DeprecationWarning: This process (pid=82) is multi-threaded, use of fork() may lead to deadlocks in the child.
  pid = os.fork()

[2024-09-03T17:59:35.056+0000] {standard_task_runner.py:63} INFO - Started process 125 to run task
[2024-09-03T17:59:35.074+0000] {standard_task_runner.py:90} INFO - Running: ['***', 'tasks', 'run', 'solar_adoption_dag', 'load_TractRecords__fct', 'manual__2024-09-03T17:59:06.450178+00:00', '--job-id', '29', '--raw', '--subdir', 'DAGS_FOLDER/etl_dag.py', '--cfg-path', '/tmp/tmpxma0nis1']
[2024-09-03T17:59:35.113+0000] {standard_task_runner.py:91} INFO - Job 29: Subtask load_TractRecords__fct
[2024-09-03T17:59:35.451+0000] {task_command.py:426} INFO - Running <TaskInstance: solar_adoption_dag.load_TractRecords__fct manual__2024-09-03T17:59:06.450178+00:00 [running]> on host fdc592a3d39f
[2024-09-03T17:59:35.874+0000] {taskinstance.py:2648} INFO - Exporting env vars: AIRFLOW_CTX_DAG_OWNER='***' AIRFLOW_CTX_DAG_ID='solar_adoption_dag' AIRFLOW_CTX_TASK_ID='load_TractRecords__fct' AIRFLOW_CTX_EXECUTION_DATE='2024-09-03T17:59:06.450178+00:00' AIRFLOW_CTX_TRY_NUMBER='1' AIRFLOW_CTX_DAG_RUN_ID='manual__2024-09-03T17:59:06.450178+00:00'
[2024-09-03T17:59:35.883+0000] {taskinstance.py:430} INFO - ::endgroup::
[2024-09-03T17:59:36.076+0000] {taskinstance.py:441} INFO - ::group::Post task execution logs
[2024-09-03T17:59:36.080+0000] {taskinstance.py:2905} ERROR - Task failed with exception
Traceback (most recent call last):
  File "/home/airflow/.local/lib/python3.12/site-packages/airflow/models/taskinstance.py", line 465, in _execute_task
    result = _execute_callable(context=context, **execute_callable_kwargs)
             ^^^^^^^^^^^^^^^^^^^^^^^^^^^^^^^^^^^^^^^^^^^^^^^^^^^^^^^^^^^^^
  File "/home/airflow/.local/lib/python3.12/site-packages/airflow/models/taskinstance.py", line 432, in _execute_callable
    return execute_callable(context=context, **execute_callable_kwargs)
           ^^^^^^^^^^^^^^^^^^^^^^^^^^^^^^^^^^^^^^^^^^^^^^^^^^^^^^^^^^^^
  File "/home/airflow/.local/lib/python3.12/site-packages/airflow/models/baseoperator.py", line 401, in wrapper
    return func(self, *args, **kwargs)
           ^^^^^^^^^^^^^^^^^^^^^^^^^^^
  File "/home/airflow/.local/lib/python3.12/site-packages/airflow/operators/python.py", line 235, in execute
    return_value = self.execute_callable()
                   ^^^^^^^^^^^^^^^^^^^^^^^
  File "/home/airflow/.local/lib/python3.12/site-packages/airflow/operators/python.py", line 252, in execute_callable
    return self.python_callable(*self.op_args, **self.op_kwargs)
           ^^^^^^^^^^^^^^^^^^^^^^^^^^^^^^^^^^^^^^^^^^^^^^^^^^^^^
  File "/opt/airflow/dags/etl_scripts/airflow_pipeline.py", line 127, in load_fact_data
    conn = create_engine(db_url)
           ^^^^^^^^^^^^^^^^^^^^^
  File "<string>", line 2, in create_engine
  File "/home/airflow/.local/lib/python3.12/site-packages/sqlalchemy/util/deprecations.py", line 375, in warned
    return fn(*args, **kwargs)
           ^^^^^^^^^^^^^^^^^^^
  File "/home/airflow/.local/lib/python3.12/site-packages/sqlalchemy/engine/create.py", line 518, in create_engine
    entrypoint = u._get_entrypoint()
                 ^^^^^^^^^^^^^^^^^^^
  File "/home/airflow/.local/lib/python3.12/site-packages/sqlalchemy/engine/url.py", line 662, in _get_entrypoint
    cls = registry.load(name)
          ^^^^^^^^^^^^^^^^^^^
  File "/home/airflow/.local/lib/python3.12/site-packages/sqlalchemy/util/langhelpers.py", line 343, in load
    raise exc.NoSuchModuleError(
sqlalchemy.exc.NoSuchModuleError: Can't load plugin: sqlalchemy.dialects:postgres.psycopg2
[2024-09-03T17:59:36.205+0000] {taskinstance.py:1206} INFO - Marking task as FAILED. dag_id=solar_adoption_dag, task_id=load_TractRecords__fct, run_id=manual__2024-09-03T17:59:06.450178+00:00, execution_date=20240903T175906, start_date=20240903T175934, end_date=20240903T175936
[2024-09-03T17:59:36.285+0000] {standard_task_runner.py:110} ERROR - Failed to execute job 29 for task load_TractRecords__fct (Can't load plugin: sqlalchemy.dialects:postgres.psycopg2; 125)
[2024-09-03T17:59:36.315+0000] {local_task_job_runner.py:240} INFO - Task exited with return code 1
[2024-09-03T17:59:36.395+0000] {taskinstance.py:3503} INFO - 0 downstream tasks scheduled from follow-on schedule check
[2024-09-03T17:59:36.417+0000] {local_task_job_runner.py:222} INFO - ::endgroup::
