[2024-09-07T19:53:53.942+0000] {local_task_job_runner.py:120} INFO - ::group::Pre task execution logs
[2024-09-07T19:53:54.033+0000] {taskinstance.py:2076} INFO - Dependencies all met for dep_context=non-requeueable deps ti=<TaskInstance: solar_adoption_dag.load_State_dim manual__2024-09-07T19:53:44.526541+00:00 [queued]>
[2024-09-07T19:53:54.414+0000] {taskinstance.py:2076} INFO - Dependencies all met for dep_context=requeueable deps ti=<TaskInstance: solar_adoption_dag.load_State_dim manual__2024-09-07T19:53:44.526541+00:00 [queued]>
[2024-09-07T19:53:54.416+0000] {taskinstance.py:2306} INFO - Starting attempt 1 of 1
[2024-09-07T19:53:54.504+0000] {taskinstance.py:2330} INFO - Executing <Task(PythonOperator): load_State_dim> on 2024-09-07 19:53:44.526541+00:00
[2024-09-07T19:53:54.520+0000] {warnings.py:112} WARNING - /home/***/.local/lib/python3.12/site-packages/***/task/task_runner/standard_task_runner.py:61: DeprecationWarning: This process (pid=94) is multi-threaded, use of fork() may lead to deadlocks in the child.
  pid = os.fork()

[2024-09-07T19:53:54.525+0000] {standard_task_runner.py:63} INFO - Started process 105 to run task
[2024-09-07T19:53:54.529+0000] {standard_task_runner.py:90} INFO - Running: ['***', 'tasks', 'run', 'solar_adoption_dag', 'load_State_dim', 'manual__2024-09-07T19:53:44.526541+00:00', '--job-id', '8', '--raw', '--subdir', 'DAGS_FOLDER/etl_dag.py', '--cfg-path', '/tmp/tmpk6mzrrzo']
[2024-09-07T19:53:54.541+0000] {standard_task_runner.py:91} INFO - Job 8: Subtask load_State_dim
[2024-09-07T19:53:54.655+0000] {task_command.py:426} INFO - Running <TaskInstance: solar_adoption_dag.load_State_dim manual__2024-09-07T19:53:44.526541+00:00 [running]> on host d49a8c6f87aa
[2024-09-07T19:53:54.825+0000] {taskinstance.py:2648} INFO - Exporting env vars: AIRFLOW_CTX_DAG_OWNER='***' AIRFLOW_CTX_DAG_ID='solar_adoption_dag' AIRFLOW_CTX_TASK_ID='load_State_dim' AIRFLOW_CTX_EXECUTION_DATE='2024-09-07T19:53:44.526541+00:00' AIRFLOW_CTX_TRY_NUMBER='1' AIRFLOW_CTX_DAG_RUN_ID='manual__2024-09-07T19:53:44.526541+00:00'
[2024-09-07T19:53:54.827+0000] {taskinstance.py:430} INFO - ::endgroup::
[2024-09-07T19:53:54.972+0000] {taskinstance.py:441} INFO - ::group::Post task execution logs
[2024-09-07T19:53:54.974+0000] {taskinstance.py:2905} ERROR - Task failed with exception
Traceback (most recent call last):
  File "/home/airflow/.local/lib/python3.12/site-packages/sqlalchemy/engine/base.py", line 1910, in _execute_context
    self.dialect.do_execute(
  File "/home/airflow/.local/lib/python3.12/site-packages/sqlalchemy/engine/default.py", line 736, in do_execute
    cursor.execute(statement, parameters)
psycopg2.errors.FeatureNotSupported: whole row unique index inference specifications are not supported


The above exception was the direct cause of the following exception:

Traceback (most recent call last):
  File "/home/airflow/.local/lib/python3.12/site-packages/airflow/models/taskinstance.py", line 465, in _execute_task
    result = _execute_callable(context=context, **execute_callable_kwargs)
             ^^^^^^^^^^^^^^^^^^^^^^^^^^^^^^^^^^^^^^^^^^^^^^^^^^^^^^^^^^^^^
  File "/home/airflow/.local/lib/python3.12/site-packages/airflow/models/taskinstance.py", line 432, in _execute_callable
    return execute_callable(context=context, **execute_callable_kwargs)
           ^^^^^^^^^^^^^^^^^^^^^^^^^^^^^^^^^^^^^^^^^^^^^^^^^^^^^^^^^^^^
  File "/home/airflow/.local/lib/python3.12/site-packages/airflow/models/baseoperator.py", line 401, in wrapper
    return func(self, *args, **kwargs)
           ^^^^^^^^^^^^^^^^^^^^^^^^^^^
  File "/home/airflow/.local/lib/python3.12/site-packages/airflow/operators/python.py", line 235, in execute
    return_value = self.execute_callable()
                   ^^^^^^^^^^^^^^^^^^^^^^^
  File "/home/airflow/.local/lib/python3.12/site-packages/airflow/operators/python.py", line 252, in execute_callable
    return self.python_callable(*self.op_args, **self.op_kwargs)
           ^^^^^^^^^^^^^^^^^^^^^^^^^^^^^^^^^^^^^^^^^^^^^^^^^^^^^
  File "/opt/airflow/dags/etl_scripts/airflow_pipeline.py", line 127, in load_data
    pd.read_parquet(table_file).to_sql(table_name, conn, if_exists='append', index=False, method=insert_on_conflict_nothing)
  File "/home/airflow/.local/lib/python3.12/site-packages/pandas/util/_decorators.py", line 333, in wrapper
    return func(*args, **kwargs)
           ^^^^^^^^^^^^^^^^^^^^^
  File "/home/airflow/.local/lib/python3.12/site-packages/pandas/core/generic.py", line 3008, in to_sql
    return sql.to_sql(
           ^^^^^^^^^^^
  File "/home/airflow/.local/lib/python3.12/site-packages/pandas/io/sql.py", line 788, in to_sql
    return pandas_sql.to_sql(
           ^^^^^^^^^^^^^^^^^^
  File "/home/airflow/.local/lib/python3.12/site-packages/pandas/io/sql.py", line 1958, in to_sql
    total_inserted = sql_engine.insert_records(
                     ^^^^^^^^^^^^^^^^^^^^^^^^^^
  File "/home/airflow/.local/lib/python3.12/site-packages/pandas/io/sql.py", line 1507, in insert_records
    raise err
  File "/home/airflow/.local/lib/python3.12/site-packages/pandas/io/sql.py", line 1498, in insert_records
    return table.insert(chunksize=chunksize, method=method)
           ^^^^^^^^^^^^^^^^^^^^^^^^^^^^^^^^^^^^^^^^^^^^^^^^
  File "/home/airflow/.local/lib/python3.12/site-packages/pandas/io/sql.py", line 1059, in insert
    num_inserted = exec_insert(conn, keys, chunk_iter)
                   ^^^^^^^^^^^^^^^^^^^^^^^^^^^^^^^^^^^
  File "/opt/airflow/dags/etl_scripts/airflow_pipeline.py", line 124, in insert_on_conflict_nothing
    result = conn.execute(stmt)
             ^^^^^^^^^^^^^^^^^^
  File "/home/airflow/.local/lib/python3.12/site-packages/sqlalchemy/engine/base.py", line 1385, in execute
    return meth(self, multiparams, params, _EMPTY_EXECUTION_OPTS)
           ^^^^^^^^^^^^^^^^^^^^^^^^^^^^^^^^^^^^^^^^^^^^^^^^^^^^^^
  File "/home/airflow/.local/lib/python3.12/site-packages/sqlalchemy/sql/elements.py", line 334, in _execute_on_connection
    return connection._execute_clauseelement(
           ^^^^^^^^^^^^^^^^^^^^^^^^^^^^^^^^^^
  File "/home/airflow/.local/lib/python3.12/site-packages/sqlalchemy/engine/base.py", line 1577, in _execute_clauseelement
    ret = self._execute_context(
          ^^^^^^^^^^^^^^^^^^^^^^
  File "/home/airflow/.local/lib/python3.12/site-packages/sqlalchemy/engine/base.py", line 1953, in _execute_context
    self._handle_dbapi_exception(
  File "/home/airflow/.local/lib/python3.12/site-packages/sqlalchemy/engine/base.py", line 2134, in _handle_dbapi_exception
    util.raise_(
  File "/home/airflow/.local/lib/python3.12/site-packages/sqlalchemy/util/compat.py", line 211, in raise_
    raise exception
  File "/home/airflow/.local/lib/python3.12/site-packages/sqlalchemy/engine/base.py", line 1910, in _execute_context
    self.dialect.do_execute(
  File "/home/airflow/.local/lib/python3.12/site-packages/sqlalchemy/engine/default.py", line 736, in do_execute
    cursor.execute(statement, parameters)
sqlalchemy.exc.NotSupportedError: (psycopg2.errors.FeatureNotSupported) whole row unique index inference specifications are not supported

[SQL: INSERT INTO "State_dim" (state_id, s_name) VALUES (%(state_id_m0)s, %(s_name_m0)s), (%(state_id_m1)s, %(s_name_m1)s) ON CONFLICT ("State_dim") DO NOTHING]
[parameters: {'state_id_m0': 's0', 's_name_m0': ' Connecticut', 'state_id_m1': 's1', 's_name_m1': None}]
(Background on this error at: https://sqlalche.me/e/14/tw8g)
[2024-09-07T19:53:55.022+0000] {taskinstance.py:1206} INFO - Marking task as FAILED. dag_id=solar_adoption_dag, task_id=load_State_dim, run_id=manual__2024-09-07T19:53:44.526541+00:00, execution_date=20240907T195344, start_date=20240907T195354, end_date=20240907T195355
[2024-09-07T19:53:55.055+0000] {standard_task_runner.py:110} ERROR - Failed to execute job 8 for task load_State_dim ((psycopg2.errors.FeatureNotSupported) whole row unique index inference specifications are not supported

[SQL: INSERT INTO "State_dim" (state_id, s_name) VALUES (%(state_id_m0)s, %(s_name_m0)s), (%(state_id_m1)s, %(s_name_m1)s) ON CONFLICT ("State_dim") DO NOTHING]
[parameters: {'state_id_m0': 's0', 's_name_m0': ' Connecticut', 'state_id_m1': 's1', 's_name_m1': None}]
(Background on this error at: https://sqlalche.me/e/14/tw8g); 105)
[2024-09-07T19:53:55.124+0000] {local_task_job_runner.py:240} INFO - Task exited with return code 1
[2024-09-07T19:53:55.182+0000] {taskinstance.py:3503} INFO - 0 downstream tasks scheduled from follow-on schedule check
[2024-09-07T19:53:55.198+0000] {local_task_job_runner.py:222} INFO - ::endgroup::
